<?xml version="1.0" encoding="UTF-8"?><testrun name="TodoTest" project="FirstSpringboot" tests="3" started="3" failures="0" errors="1" ignored="0">
  <testsuite name="com.test.todoTest.TodoTest" time="0.11">
    <testcase name="getById_shouldReturnTodo" classname="com.test.todoTest.TodoTest" time="0.078"/>
    <testcase name="findAllTest" classname="com.test.todoTest.TodoTest" time="0.022"/>
    <testcase name="whenInvaildId_todoShouldBeNotFound" classname="com.test.todoTest.TodoTest" time="0.01">
      <error>java.lang.Exception: Unexpected exception, expected&lt;java.util.NoSuchElementException&gt; but was&lt;springboot.starter.errorHandler.NotFounException&gt;&#13;
	at org.junit.internal.runners.statements.ExpectException.evaluate(ExpectException.java:28)&#13;
	at org.springframework.test.context.junit4.statements.RunBeforeTestMethodCallbacks.evaluate(RunBeforeTestMethodCallbacks.java:75)&#13;
	at org.springframework.test.context.junit4.statements.RunAfterTestMethodCallbacks.evaluate(RunAfterTestMethodCallbacks.java:86)&#13;
	at org.springframework.test.context.junit4.statements.SpringRepeat.evaluate(SpringRepeat.java:84)&#13;
	at org.junit.runners.ParentRunner.runLeaf(ParentRunner.java:325)&#13;
	at org.springframework.test.context.junit4.SpringJUnit4ClassRunner.runChild(SpringJUnit4ClassRunner.java:251)&#13;
	at org.springframework.test.context.junit4.SpringJUnit4ClassRunner.runChild(SpringJUnit4ClassRunner.java:97)&#13;
	at org.junit.runners.ParentRunner$3.run(ParentRunner.java:290)&#13;
	at org.junit.runners.ParentRunner$1.schedule(ParentRunner.java:71)&#13;
	at org.junit.runners.ParentRunner.runChildren(ParentRunner.java:288)&#13;
	at org.junit.runners.ParentRunner.access$000(ParentRunner.java:58)&#13;
	at org.junit.runners.ParentRunner$2.evaluate(ParentRunner.java:268)&#13;
	at org.springframework.test.context.junit4.statements.RunBeforeTestClassCallbacks.evaluate(RunBeforeTestClassCallbacks.java:61)&#13;
	at org.springframework.test.context.junit4.statements.RunAfterTestClassCallbacks.evaluate(RunAfterTestClassCallbacks.java:70)&#13;
	at org.junit.runners.ParentRunner.run(ParentRunner.java:363)&#13;
	at org.springframework.test.context.junit4.SpringJUnit4ClassRunner.run(SpringJUnit4ClassRunner.java:190)&#13;
	at org.eclipse.jdt.internal.junit4.runner.JUnit4TestReference.run(JUnit4TestReference.java:86)&#13;
	at org.eclipse.jdt.internal.junit.runner.TestExecution.run(TestExecution.java:38)&#13;
	at org.eclipse.jdt.internal.junit.runner.RemoteTestRunner.runTests(RemoteTestRunner.java:459)&#13;
	at org.eclipse.jdt.internal.junit.runner.RemoteTestRunner.runTests(RemoteTestRunner.java:675)&#13;
	at org.eclipse.jdt.internal.junit.runner.RemoteTestRunner.run(RemoteTestRunner.java:382)&#13;
	at org.eclipse.jdt.internal.junit.runner.RemoteTestRunner.main(RemoteTestRunner.java:192)&#13;
Caused by: springboot.starter.errorHandler.NotFounException: no record found for id [1] in database.&#13;
	at springboot.starter.service.TodoService.getTodoById(TodoService.java:26)&#13;
	at com.test.todoTest.TodoTest.whenInvaildId_todoShouldBeNotFound(TodoTest.java:74)&#13;
	at sun.reflect.NativeMethodAccessorImpl.invoke0(Native Method)&#13;
	at sun.reflect.NativeMethodAccessorImpl.invoke(Unknown Source)&#13;
	at sun.reflect.DelegatingMethodAccessorImpl.invoke(Unknown Source)&#13;
	at java.lang.reflect.Method.invoke(Unknown Source)&#13;
	at org.junit.runners.model.FrameworkMethod$1.runReflectiveCall(FrameworkMethod.java:50)&#13;
	at org.junit.internal.runners.model.ReflectiveCallable.run(ReflectiveCallable.java:12)&#13;
	at org.junit.runners.model.FrameworkMethod.invokeExplosively(FrameworkMethod.java:47)&#13;
	at org.junit.internal.runners.statements.InvokeMethod.evaluate(InvokeMethod.java:17)&#13;
	at org.springframework.test.context.junit4.statements.RunBeforeTestExecutionCallbacks.evaluate(RunBeforeTestExecutionCallbacks.java:73)&#13;
	at org.springframework.test.context.junit4.statements.RunAfterTestExecutionCallbacks.evaluate(RunAfterTestExecutionCallbacks.java:83)&#13;
	at org.junit.internal.runners.statements.ExpectException.evaluate(ExpectException.java:19)&#13;
	... 21 more&#13;
&#13;
</error>
    </testcase>
  </testsuite>
</testrun>
